Workbook

Sheet All
C1: BRET | G1: Split-YFP | N1: LUMIER
A2: Protein1 | B2: Protein2 | C2: Tag1 | D2: Tag2 | E2: Mean BRET | F2: Count | G2: Tag1 | H2: Tag2 | I2: Mean YFP | J2: Mean-nodna | K2: normalized YFP | L2: Pos_Neg | M2: Platte | N2: Tag1 | O2: Tag2 | P2: Mean | Q2: Mean/nodna | R2: Pos_Neg | S2: Plattte
A3: ABCD1 | B3: ALDH3A2 | C3: C-hRluc | D3: N-Venus | E3: 0.055 | F3: 1 | G3: YFP1 | H3: YFP2 | I3: 1867 | J3: =I3-'Controls-Split'!$D$4 -> 369 | K3: =J3/'Controls-Split'!$C$4 -> 0.0066757123 | L3: =IF(K3>'Controls-Split'!$I$4,"Pos","Neg") -> Neg | M3: 1 | N3: N-hRluc | O3: V5 | P3: 3860 | Q3: =P3/'Controls-Split'!$D$32 -> 1.5545711 | R3: =IF(Q3>'Controls-Split'!$J$32,"Pos","Neg") -> Neg | S3: 9
A4: ABCD1 | B4: EHHADH | C4: C-hRluc | D4: C-Venus | E4: 0.03 | F4: 2 | G4: YFP1 | H4: YFP2 | I4: 1746 | J4: =I4-'Controls-Split'!$D$4 -> 248 | K4: =J4/'Controls-Split'!$C$4 -> 0.0044866576 | L4: =IF(K4>'Controls-Split'!$I$4,"Pos","Neg") -> Neg | M4: 1 | N4: N-hRluc | O4: V5 | P4: 2344 | Q4: =P4/'Controls-Split'!$D$27 -> 1.1406326 | R4: =IF(Q4>'Controls-Split'!$J$27,"Pos","Neg") -> Neg | S4: 4
A5: ABCD1 | B5: FAR1 | C5: C-hRluc | D5: N-Venus | E5: 0.039 | F5: 2 | G5: YFP1 | H5: YFP2 | I5: 1751 | J5: =I5-'Controls-Split'!$D$4 -> 253 | K5: =J5/'Controls-Split'!$C$4 -> 0.0045771144 | L5: =IF(K5>'Controls-Split'!$I$4,"Pos","Neg") -> Neg | M5: 1 | N5: N-hRluc | O5: V5 | P5: 2658 | Q5: =P5/'Controls-Split'!$D$32 -> 1.0704793 | R5: =IF(Q5>'Controls-Split'!$J$32,"Pos","Neg") -> Neg | S5: 9
A6: ABCD1 | B6: PEX13 | C6: C-hRluc | D6: N-Venus | E6: 0.029 | F6: 2 | G6: YFP1 | H6: YFP2 | I6: 1769 | J6: =I6-'Controls-Split'!$D$4 -> 271 | K6: =J6/'Controls-Split'!$C$4 -> 0.0049027589 | L6: =IF(K6>'Controls-Split'!$I$4,"Pos","Neg") -> Neg | M6: 1 | N6: N-hRluc | O6: V5 | P6: 1253 | Q6: =P6/'Controls-Split'!$D$30 -> 0.96533128 | R6: =IF(Q6>'Controls-Split'!$J$30,"Pos","Neg") -> Neg | S6: 7
A7: ABCD1 | B7: PEX5d | C7: N-hRluc | D7: N-Venus | E7: 0.033 | F7: 2 | G7: YFP1 | H7: YFP2 | I7: 3677 | J7: =I7-'Controls-Split'!$D$4 -> 2179 | K7: =J7/'Controls-Split'!$C$4 -> 0.039421076 | L7: =IF(K7>'Controls-Split'!$I$4,"Pos","Neg") -> Neg | M7: 1
A8: ABCD1 | B8: PXT1 | C8: C-hRluc | D8: C-Venus | E8: 0.03 | F8: 1 | G8: YFP1 | H8: YFP2 | I8: 2246 | J8: =I8-'Controls-Split'!$D$4 -> 748 | K8: =J8/'Controls-Split'!$C$4 -> 0.013532338 | L8: =IF(K8>'Controls-Split'!$I$4,"Pos","Neg") -> Neg | M8: 1 | N8: N-hRluc | O8: V5 | P8: 1933 | Q8: =P8/'Controls-Split'!$D$26 -> 0.99793495 | R8: =IF(Q8>'Controls-Split'!$J$26,"Pos","Neg") -> Neg | S8: 3
A9: ABCD3b | B9: FIS1 | C9: N-hRluc | D9: N-Venus | E9: 0.066 | F9: 2 | G9: YFP1 | H9: YFP2 | I9: 1826 | J9: =I9-'Controls-Split'!$D$4 -> 328 | K9: =J9/'Controls-Split'!$C$4 -> 0.0059339665 | L9: =IF(K9>'Controls-Split'!$I$4,"Pos","Neg") -> Neg | M9: 1 | N9: N-hRluc | O9: V5 | P9: 569 | Q9: =P9/'Controls-Split'!$D$35 -> 0.38999315 | R9: =IF(Q9>'Controls-Split'!$J$35,"Pos","Neg") -> Neg | S9: 12
A10: ABCD3b | B10: FNDC5 | C10: N-hRluc | D10: N-Venus | E10: 0.028 | F10: 2 | G10: YFP1 | H10: YFP2 | I10: 1708 | J10: =I10-'Controls-Split'!$D$4 -> 210 | K10: =J10/'Controls-Split'!$C$4 -> 0.0037991859 | L10: =IF(K10>'Controls-Split'!$I$4,"Pos","Neg") -> Neg | M10: 1 | N10: N-hRluc | O10: V5 | P10: 684 | Q10: =P10/'Controls-Split'!$D$35 -> 0.46881426 | R10: =IF(Q10>'Controls-Split'!$J$35,"Pos","Neg") -> Neg | S10: 12
A11: ABCD4 | B11: ABCD4 | C11: C-hRluc | D11: N-Venus | E11: 0.108 | F11: 2 | G11: YFP1 | H11: YFP2 | I11: 2427 | J11: =I11-'Controls-Split'!$D$4 -> 929 | K11: =J11/'Controls-Split'!$C$4 -> 0.016806875 | L11: =IF(K11>'Controls-Split'!$I$4,"Pos","Neg") -> Neg | M11: 1 | N11: N-hRluc | O11: V5 | P11: 4724 | Q11: =P11/'Controls-Split'!$D$31 -> 1.7515758 | R11: =IF(Q11>'Controls-Split'!$J$31,"Pos","Neg") -> Pos | S11: 8
A12: ABCD4 | B12: ACOX2 | C12: C-hRluc | D12: N-Venus | E12: 0.034 | F12: 2 | G12: YFP1 | H12: YFP2 | I12: 1617 | J12: =I12-'Controls-Split'!$D$4 -> 119 | K12: =J12/'Controls-Split'!$C$4 -> 0.002152872 | L12: =IF(K12>'Controls-Split'!$I$4,"Pos","Neg") -> Neg | M12: 1 | N12: N-hRluc | O12: V5 | P12: 8134 | Q12: =P12/'Controls-Split'!$D$32 -> 3.275876 | R12: =IF(Q12>'Controls-Split'!$J$32,"Pos","Neg") -> Pos | S12: 9
A13: ABCD4 | B13: PRDX1 | C13: N-Venus | D13: C-hRluc | E13: 0.041 | F13: 2 | G13: YFP2 | H13: YFP1 | I13: 1911 | J13: =I13-'Controls-Split'!$D$4 -> 413 | K13: =J13/'Controls-Split'!$C$4 -> 0.0074717322 | L13: =IF(K13>'Controls-Split'!$I$4,"Pos","Neg") -> Neg | M13: 1 | N13: V5 | O13: N-hRluc | P13: 7080 | Q13: =P13/'Controls-Split'!$D$31 -> 2.625139 | R13: =IF(Q13>'Controls-Split'!$J$31,"Pos","Neg") -> Pos | S13: 8
A14: ABCD4 | B14: PXT1 | C14: N-Venus | D14: N-hRluc | E14: 0.032 | F14: 2 | G14: YFP2 | H14: YFP1 | I14: 1872 | J14: =I14-'Controls-Split'!$D$4 -> 374 | K14: =J14/'Controls-Split'!$C$4 -> 0.0067661692 | L14: =IF(K14>'Controls-Split'!$I$4,"Pos","Neg") -> Neg | M14: 1 | N14: V5 | O14: N-hRluc | P14: 1191 | Q14: =P14/'Controls-Split'!$D$31 -> 0.44160178 | R14: =IF(Q14>'Controls-Split'!$J$31,"Pos","Neg") -> Neg | S14: 8
A15: ABCD4 | B15: SLC22A5 | C15: N-Venus | D15: N-hRluc | E15: 0.028 | F15: 2 | G15: YFP2 | H15: YFP1 | I15: 1544 | J15: =I15-'Controls-Split'!$D$4 -> 46 | K15: =J15/'Controls-Split'!$C$4 -> 0.00083220262 | L15: =IF(K15>'Controls-Split'!$I$4,"Pos","Neg") -> Neg | M15: 1 | N15: V5 | O15: N-hRluc | P15: 5605 | Q15: =P15/'Controls-Split'!$D$31 -> 2.0782351 | R15: =IF(Q15>'Controls-Split'!$J$31,"Pos","Neg") -> Pos | S15: 8
A16: ABCD4 | B16: SOD1 | C16: C-hRluc | D16: C-Venus | E16: 0.053 | F16: 2 | G16: YFP1 | H16: YFP2 | I16: 2722 | J16: =I16-'Controls-Split'!$D$4 -> 1224 | K16: =J16/'Controls-Split'!$C$4 -> 0.022143826 | L16: =IF(K16>'Controls-Split'!$I$4,"Pos","Neg") -> Neg | M16: 1 | N16: N-hRluc | O16: V5 | P16: 1222 | Q16: =P16/'Controls-Split'!$D$30 -> 0.94144838 | R16: =IF(Q16>'Controls-Split'!$J$30,"Pos","Neg") -> Neg | S16: 7
A17: ACAA1a | B17: ACAA1a | C17: C-hRluc | D17: N-Venus | E17: 0.182 | F17: 2 | G17: YFP1 | H17: YFP2 | I17: 4841 | J17: =I17-'Controls-Split'!$D$4 -> 3343 | K17: =J17/'Controls-Split'!$C$4 -> 0.060479421 | L17: =IF(K17>'Controls-Split'!$I$4,"Pos","Neg") -> Pos | M17: 1 | N17: N-hRluc | O17: V5 | P17: 2467 | Q17: =P17/'Controls-Split'!$D$34 -> 1.8904215 | R17: =IF(Q17>'Controls-Split'!$J$34,"Pos","Neg") -> Neg | S17: 11
A18: ACAA1a | B18: GSTK1a | C18: N-Venus | D18: C-hRluc | E18: 0.03 | F18: 1 | G18: YFP2 | H18: YFP1 | I18: 3315 | J18: =I18-'Controls-Split'!$D$4 -> 1817 | K18: =J18/'Controls-Split'!$C$4 -> 0.032872004 | L18: =IF(K18>'Controls-Split'!$I$4,"Pos","Neg") -> Neg | M18: 1 | N18: V5 | O18: N-hRluc | P18: 1724 | Q18: =P18/'Controls-Split'!$D$34 -> 1.3210728 | R18: =IF(Q18>'Controls-Split'!$J$34,"Pos","Neg") -> Neg | S18: 11
A19: ACAA1a | B19: PMVK | C19: N-Venus | D19: C-hRluc | E19: 0.032 | F19: 2 | G19: YFP2 | H19: YFP1 | I19: 7079 | J19: =I19-'Controls-Split'!$D$4 -> 5581 | K19: =J19/'Controls-Split'!$C$4 -> 0.10096789 | L19: =IF(K19>'Controls-Split'!$I$4,"Pos","Neg") -> Pos | M19: 1 | N19: V5 | O19: N-hRluc | P19: 630 | Q19: =P19/'Controls-Split'!$D$35 -> 0.4318026 | R19: =IF(Q19>'Controls-Split'!$J$35,"Pos","Neg") -> Neg | S19: 12
A20: ACAA1a | B20: PXT1 | C20: C-hRluc | D20: C-Venus | E20: 0.03 | F20: 1 | G20: YFP1 | H20: YFP2 | I20: 1962 | J20: =I20-'Controls-Split'!$D$4 -> 464 | K20: =J20/'Controls-Split'!$C$4 -> 0.0083943917 | L20: =IF(K20>'Controls-Split'!$I$4,"Pos","Neg") -> Neg | M20: 1 | N20: N-hRluc | O20: V5 | P20: 1791 | Q20: =P20/'Controls-Split'!$D$26 -> 0.92462571 | R20: =IF(Q20>'Controls-Split'!$J$26,"Pos","Neg") -> Neg | S20: 3
A21: ACAA1a | B21: TYSND1 | C21: C-Venus | D21: C-hRluc | E21: 0.028 | F21: 2 | G21: YFP2 | H21: YFP1 | I21: 2079 | J21: =I21-'Controls-Split'!$D$4 -> 581 | K21: =J21/'Controls-Split'!$C$4 -> 0.010511081 | L21: =IF(K21>'Controls-Split'!$I$4,"Pos","Neg") -> Neg | M21: 1
A22: ACAA1b | B22: ACOT1 | C22: C-hRluc | D22: N-Venus | E22: 0.027 | F22: 1 | G22: YFP1 | H22: YFP2 | I22: 2150 | J22: =I22-'Controls-Split'!$D$4 -> 652 | K22: =J22/'Controls-Split'!$C$4 -> 0.011795568 | L22: =IF(K22>'Controls-Split'!$I$4,"Pos","Neg") -> Neg | M22: 1 | N22: N-hRluc | O22: V5 | P22: 1060 | Q22: =P22/'Controls-Split'!$D$34 -> 0.81226054 | R22: =IF(Q22>'Controls-Split'!$J$34,"Pos","Neg") -> Neg | S22: 11
A23: ACAA1b | B23: DAO | C23: C-hRluc | D23: C-Venus | E23: 0.033 | F23: 1 | G23: YFP1 | H23: YFP2 | I23: 1816 | J23: =I23-'Controls-Split'!$D$4 -> 318 | K23: =J23/'Controls-Split'!$C$4 -> 0.0057530529 | L23: =IF(K23>'Controls-Split'!$I$4,"Pos","Neg") -> Neg | M23: 1 | N23: N-hRluc | O23: V5 | P23: 1160 | Q23: =P23/'Controls-Split'!$D$35 -> 0.79506511 | R23: =IF(Q23>'Controls-Split'!$J$35,"Pos","Neg") -> Neg | S23: 12
A24: ACAA1b | B24: FIS1 | C24: N-hRluc | D24: C-Venus | E24: 0.054 | F24: 2 | G24: YPF1 | H24: YFP2 | I24: 1614 | J24: =I24-'Controls-Split'!$D$4 -> 116 | K24: =J24/'Controls-Split'!$C$4 -> 0.0020985979 | L24: =IF(K24>'Controls-Split'!$I$4,"Pos","Neg") -> Neg | M24: 1 | N24: N-hRluc | O24: V5 | P24: 1106 | Q24: =P24/'Controls-Split'!$D$29 -> 0.89699919 | R24: =IF(Q24>'Controls-Split'!$J$29,"Pos","Neg") -> Neg | S24: 6
A25: ACAA1b | B25: GSTK1a | C25: C-hRluc | D25: N-Venus | E25: 0.043 | F25: 1 | G25: YFP1 | H25: YFP2 | I25: 3511 | J25: =I25-'Controls-Split'!$D$4 -> 2013 | K25: =J25/'Controls-Split'!$C$4 -> 0.03641791 | L25: =IF(K25>'Controls-Split'!$I$4,"Pos","Neg") -> Neg | M25: 1 | N25: N-hRluc | O25: V5 | P25: 939 | Q25: =P25/'Controls-Split'!$D$28 -> 0.6276738 | R25: =IF(Q25>'Controls-Split'!$J$28,"Pos","Neg") -> Neg | S25: 5
A26: ACAA1b | B26: SLC27A2 | C26: N-Venus | D26: C-hRluc | E26: 0.033 | F26: 2 | G26: YFP2 | H26: YFP1 | I26: 1960 | J26: =I26-'Controls-Split'!$D$4 -> 462 | K26: =J26/'Controls-Split'!$C$4 -> 0.008358209 | L26: =IF(K26>'Controls-Split'!$I$4,"Pos","Neg") -> Neg | M26: 1 | N26: V5 | O26: N-hRluc | P26: 2086 | Q26: =P26/'Controls-Split'!$D$34 -> 1.5984674 | R26: =IF(Q26>'Controls-Split'!$J$34,"Pos","Neg") -> Neg | S26: 11
A27: ACAA1b | B27: TYSND1 | C27: N-hRluc | D27: N-Venus | E27: 0.038 | F27: 2 | G27: YFP1 | H27: YFP2 | I27: 2102 | J27: =I27-'Controls-Split'!$D$4 -> 604 | K27: =J27/'Controls-Split'!$C$4 -> 0.010927182 | L27: =IF(K27>'Controls-Split'!$I$4,"Pos","Neg") -> Neg | M27: 1 | N27: N-hRluc | O27: V5 | P27: 2547 | Q27: =P27/'Controls-Split'!$D$32 -> 1.0257753 | R27: =IF(Q27>'Controls-Split'!$J$32,"Pos","Neg") -> Neg | S27: 9
A28: ACAD11 | B28: TYSND1 | C28: N-hRluc | D28: N-Venus | E28: 0.053 | F28: 2 | G28: YFP1 | H28: YFP2 | I28: 1968 | J28: =I28-'Controls-Split'!$D$4 -> 470 | K28: =J28/'Controls-Split'!$C$4 -> 0.0085029398 | L28: =IF(K28>'Controls-Split'!$I$4,"Pos","Neg") -> Neg | M28: 1 | N28: N-hRluc | O28: V5 | P28: 1527 | Q28: =P28/'Controls-Split'!$D$32 -> 0.61498188 | R28: =IF(Q28>'Controls-Split'!$J$32,"Pos","Neg") -> Neg | S28: 9
A29: ACOT2v1 | B29: AGXT | C29: C-hRluc | D29: N-Venus | E29: 0.034 | F29: 1 | G29: YFP1 | H29: YFP2 | I29: 3119 | J29: =I29-'Controls-Split'!$D$4 -> 1621 | K29: =J29/'Controls-Split'!$C$4 -> 0.029326097 | L29: =IF(K29>'Controls-Split'!$I$4,"Pos","Neg") -> Neg | M29: 1 | N29: N-hRluc | O29: V5 | P29: 1805 | Q29: =P29/'Controls-Split'!$D$32 -> 0.72694321 | R29: =IF(Q29>'Controls-Split'!$J$32,"Pos","Neg") -> Neg | S29: 9
A30: ACOT2v2 | B30: DHRS4 | C30: N-Venus | D30: N-hRluc | E30: 0.031 | F30: 2 | G30: YFP2 | H30: YFP1 | I30: 1736 | J30: =I30-'Controls-Split'!$D$4 -> 238 | K30: =J30/'Controls-Split'!$C$4 -> 0.004305744 | L30: =IF(K30>'Controls-Split'!$I$4,"Pos","Neg") -> Neg | M30: 1 | N30: V5 | O30: N-hRluc | P30: 566 | Q30: =P30/'Controls-Split'!$D$30 -> 0.43605547 | R30: =IF(Q30>'Controls-Split'!$J$30,"Pos","Neg") -> Neg | S30: 7
A31: ACOT8 | B31: ACOT8 | C31: N-hRluc | D31: N-Venus | E31: 0.113 | F31: 2 | G31: YFP1 | H31: YFP2 | I31: 3140 | J31: =I31-'Controls-Split'!$D$4 -> 1642 | K31: =J31/'Controls-Split'!$C$4 -> 0.029706015 | L31: =IF(K31>'Controls-Split'!$I$4,"Pos","Neg") -> Neg | M31: 1 | N31: N-hRluc | O31: V5 | P31: 2342 | Q31: =P31/'Controls-Split'!$D$34 -> 1.794636 | R31: =IF(Q31>'Controls-Split'!$J$34,"Pos","Neg") -> Neg | S31: 11
A32: ACOT8 | B32: DHRS4 | C32: N-Venus | D32: N-hRluc | E32: 0.039 | F32: 1 | G32: YFP2 | H32: YFP1 | I32: 2076 | J32: =I32-'Controls-Split'!$D$4 -> 578 | K32: =J32/'Controls-Split'!$C$4 -> 0.010456807 | L32: =IF(K32>'Controls-Split'!$I$4,"Pos","Neg") -> Neg | M32: 1 | N32: V5 | O32: N-hRluc | P32: 821 | Q32: =P32/'Controls-Split'!$D$34 -> 0.62911877 | R32: =IF(Q32>'Controls-Split'!$J$34,"Pos","Neg") -> Neg | S32: 11
A33: ACOT8 | B33: HAO1 | C33: N-Venus | D33: N-hRluc | E33: 0.031 | F33: 2 | G33: YFP2 | H33: YFP1 | I33: 2190 | J33: =I33-'Controls-Split'!$D$4 -> 692 | K33: =J33/'Controls-Split'!$C$4 -> 0.012519222 | L33: =IF(K33>'Controls-Split'!$I$4,"Pos","Neg") -> Neg | M33: 1 | N33: V5 | O33: N-hRluc | P33: 1021 | Q33: =P33/'Controls-Split'!$D$34 -> 0.78237548 | R33: =IF(Q33>'Controls-Split'!$J$34,"Pos","Neg") -> Neg | S33: 11
A34: ACOT8 | B34: TYSND1 | C34: N-hRluc | D34: N-Venus | E34: 0.03 | F34: 2 | G34: YFP1 | H34: YFP2 | I34: 2098 | J34: =I34-'Controls-Split'!$D$4 -> 600 | K34: =J34/'Controls-Split'!$C$4 -> 0.010854817 | L34: =IF(K34>'Controls-Split'!$I$4,"Pos","Neg") -> Neg | M34: 1 | N34: N-hRluc | O34: V5 | P34: 3544 | Q34: =P34/'Controls-Split'!$D$32 -> 1.4273057 | R34: =IF(Q34>'Controls-Split'!$J$32,"Pos","Neg") -> Neg | S34: 9
A35: ACOX1 | B35: GSTK1b | C35: N-hRluc | D35: N-Venus | E35: 0.027 | F35: 2 | G35: YFP1 | H35: YFP2 | I35: 2121 | J35: =I35-'Controls-Split'!$D$4 -> 623 | K35: =J35/'Controls-Split'!$C$4 -> 0.011270918 | L35: =IF(K35>'Controls-Split'!$I$4,"Pos","Neg") -> Neg | M35: 1 | N35: N-hRluc | O35: V5 | P35: 1330 | Q35: =P35/'Controls-Split'!$D$28 -> 0.88903743 | R35: =IF(Q35>'Controls-Split'!$J$28,"Pos","Neg") -> Neg | S35: 5
A36: ACOX1 | B36: IDH1 | C36: N-hRluc | D36: N-Venus | E36: 0.035 | F36: 2 | G36: YFP1 | H36: YFP2 | I36: 1813 | J36: =I36-'Controls-Split'!$D$4 -> 315 | K36: =J36/'Controls-Split'!$C$4 -> 0.0056987788 | L36: =IF(K36>'Controls-Split'!$I$4,"Pos","Neg") -> Neg | M36: 1 | N36: N-hRluc | O36: V5 | P36: 1300 | Q36: =P36/'Controls-Split'!$D$28 -> 0.86898396 | R36: =IF(Q36>'Controls-Split'!$J$28,"Pos","Neg") -> Neg | S36: 5
A37: PEX19 | B37: ACAD11 | C37: N-Venus | D37: N-hRluc | E37: 0.046 | F37: 2 | G37: YFP2 | H37: YFP1 | I37: 5694 | J37: =I37-'Controls-Split'!$D$14 -> 4905 | K37: =J37/'Controls-Split'!$C$14 -> 0.11539547 | L37: =IF(K37>'Controls-Split'!$I$14,"Pos","Neg") -> Pos | M37: 1 | N37: V5 | O37: N-hRluc | P37: 2779 | Q37: =P37/'Controls-Split'!$D$31 -> 1.0304042 | R37: =IF(Q37>'Controls-Split'!$J$31,"Pos","Neg") -> Neg | S37: 8
A38: SLC22A5 | B38: DNAJC10 | C38: C-Venus | D38: N-hRluc | E38: 0.057 | F38: 1 | G38: YFP2 | H38: YFP1 | I38: 1765 | J38: =I38-'Controls-Split'!$D$4 -> 267 | K38: =J38/'Controls-Split'!$C$4 -> 0.0048303935 | L38: =IF(K38>'Controls-Split'!$I$4,"Pos","Neg") -> Neg | M38: 1 | N38: V5 | O38: N-hRluc | P38: 2937 | Q38: =P38/'Controls-Split'!$D$26 -> 1.5162623 | R38: =IF(Q38>'Controls-Split'!$J$26,"Pos","Neg") -> Pos | S38: 3
A39: SLC22A5 | B39: SLC22A5 | C39: N-hRluc | D39: C-Venus | E39: 0.045 | F39: 1 | G39: YFP1 | H39: YFP2 | I39: 1750 | J39: =I39-'Controls-Split'!$D$4 -> 252 | K39: =J39/'Controls-Split'!$C$4 -> 0.0045590231 | L39: =IF(K39>'Controls-Split'!$I$4,"Pos","Neg") -> Neg | M39: 1 | N39: N-hRluc | O39: V5 | P39: 2024 | Q39: =P39/'Controls-Split'!$D$26 -> 1.0449148 | R39: =IF(Q39>'Controls-Split'!$J$26,"Pos","Neg") -> Neg | S39: 3
A40: SLC25A17 | B40: PXMP2 | C40: N-hRluc | D40: C-Venus | E40: 0.028 | F40: 1 | G40: YFP1 | H40: YFP2 | I40: 2077 | J40: =I40-'Controls-Split'!$D$4 -> 579 | K40: =J40/'Controls-Split'!$C$4 -> 0.010474898 | L40: =IF(K40>'Controls-Split'!$I$4,"Pos","Neg") -> Neg | M40: 1 | N40: N-hRluc | O40: V5 | P40: 1117 | Q40: =P40/'Controls-Split'!$D$32 -> 0.44985904 | R40: =IF(Q40>'Controls-Split'!$J$32,"Pos","Neg") -> Neg | S40: 9
...

Sheet R_ana
A1: Protein1 | B1: Protein2 | C1: BRET_Mean | D1: BRET_Count | E1: YFP_Mean | F1: YFP_Mean_Nodna | G1: YFP_normalized | H1: YFP_result | I1: LUMIER_Mean | J1: LUMIER_normalized | K1: LUMIER_result
A2: ABCD1 | B2: ALDH3A2 | C2: 0.055 | D2: 1 | E2: 1867 | F2: 369 | G2: 0.007 | H2: Neg | I2: 3860 | J2: 1.55 | K2: Neg
A3: ABCD1 | B3: EHHADH | C3: 0.03 | D3: 2 | E3: 1746 | F3: 248 | G3: 0.004 | H3: Neg | I3: 2344 | J3: 1.14 | K3: Neg
A4: ABCD1 | B4: FAR1 | C4: 0.039 | D4: 2 | E4: 1751 | F4: 253 | G4: 0.005 | H4: Neg | I4: 2658 | J4: 1.07 | K4: Neg
A5: ABCD1 | B5: PEX13 | C5: 0.029 | D5: 2 | E5: 1769 | F5: 271 | G5: 0.005 | H5: Neg | I5: 1253 | J5: 0.97 | K5: Neg
A6: ABCD1 | B6: PEX5d | C6: 0.033 | D6: 2 | E6: 3677 | F6: 2179 | G6: 0.039 | H6: Neg
A7: ABCD1 | B7: PXT1 | C7: 0.03 | D7: 1 | E7: 2246 | F7: 748 | G7: 0.014 | H7: Neg | I7: 1933 | J7: 1 | K7: Neg
A8: ABCD3b | B8: FIS1 | C8: 0.066 | D8: 2 | E8: 1826 | F8: 328 | G8: 0.006 | H8: Neg | I8: 569 | J8: 0.39 | K8: Neg
A9: ABCD3b | B9: FNDC5 | C9: 0.028 | D9: 2 | E9: 1708 | F9: 210 | G9: 0.004 | H9: Neg | I9: 684 | J9: 0.47 | K9: Neg
A10: ABCD4 | B10: ABCD4 | C10: 0.108 | D10: 2 | E10: 2427 | F10: 929 | G10: 0.017 | H10: Neg | I10: 4724 | J10: 1.75 | K10: Pos
A11: ABCD4 | B11: ACOX2 | C11: 0.034 | D11: 2 | E11: 1617 | F11: 119 | G11: 0.002 | H11: Neg | I11: 8134 | J11: 3.28 | K11: Pos
A12: ABCD4 | B12: PRDX1 | C12: 0.041 | D12: 2 | E12: 1911 | F12: 413 | G12: 0.007 | H12: Neg | I12: 7080 | J12: 2.63 | K12: Pos
A13: ABCD4 | B13: PXT1 | C13: 0.032 | D13: 2 | E13: 1872 | F13: 374 | G13: 0.007 | H13: Neg | I13: 1191 | J13: 0.44 | K13: Neg
A14: ABCD4 | B14: SLC22A5 | C14: 0.028 | D14: 2 | E14: 1544 | F14: 46 | G14: 0.001 | H14: Neg | I14: 5605 | J14: 2.08 | K14: Pos
A15: ABCD4 | B15: SOD1 | C15: 0.053 | D15: 2 | E15: 2722 | F15: 1224 | G15: 0.022 | H15: Neg | I15: 1222 | J15: 0.94 | K15: Neg
A16: ACAA1a | B16: ACAA1a | C16: 0.182 | D16: 2 | E16: 4841 | F16: 3343 | G16: 0.06 | H16: Pos | I16: 2467 | J16: 1.89 | K16: Neg
A17: ACAA1a | B17: GSTK1a | C17: 0.03 | D17: 1 | E17: 3315 | F17: 1817 | G17: 0.033 | H17: Neg | I17: 1724 | J17: 1.32 | K17: Neg
A18: ACAA1a | B18: PMVK | C18: 0.032 | D18: 2 | E18: 7079 | F18: 5581 | G18: 0.101 | H18: Pos | I18: 630 | J18: 0.43 | K18: Neg
A19: ACAA1a | B19: PXT1 | C19: 0.03 | D19: 1 | E19: 1962 | F19: 464 | G19: 0.008 | H19: Neg | I19: 1791 | J19: 0.92 | K19: Neg
A20: ACAA1a | B20: TYSND1 | C20: 0.028 | D20: 2 | E20: 2079 | F20: 581 | G20: 0.011 | H20: Neg
A21: ACAA1b | B21: ACOT1 | C21: 0.027 | D21: 1 | E21: 2150 | F21: 652 | G21: 0.012 | H21: Neg | I21: 1060 | J21: 0.81 | K21: Neg
A22: ACAA1b | B22: DAO | C22: 0.033 | D22: 1 | E22: 1816 | F22: 318 | G22: 0.006 | H22: Neg | I22: 1160 | J22: 0.8 | K22: Neg
A23: ACAA1b | B23: FIS1 | C23: 0.054 | D23: 2 | E23: 1614 | F23: 116 | G23: 0.002 | H23: Neg | I23: 1106 | J23: 0.9 | K23: Neg
A24: ACAA1b | B24: GSTK1a | C24: 0.043 | D24: 1 | E24: 3511 | F24: 2013 | G24: 0.036 | H24: Neg | I24: 939 | J24: 0.63 | K24: Neg
A25: ACAA1b | B25: SLC27A2 | C25: 0.033 | D25: 2 | E25: 1960 | F25: 462 | G25: 0.008 | H25: Neg | I25: 2086 | J25: 1.6 | K25: Neg
A26: ACAA1b | B26: TYSND1 | C26: 0.038 | D26: 2 | E26: 2102 | F26: 604 | G26: 0.011 | H26: Neg | I26: 2547 | J26: 1.03 | K26: Neg
A27: ACAD11 | B27: TYSND1 | C27: 0.053 | D27: 2 | E27: 1968 | F27: 470 | G27: 0.009 | H27: Neg | I27: 1527 | J27: 0.61 | K27: Neg
A28: ACOT2v1 | B28: AGXT | C28: 0.034 | D28: 1 | E28: 3119 | F28: 1621 | G28: 0.029 | H28: Neg | I28: 1805 | J28: 0.73 | K28: Neg
A29: ACOT2v2 | B29: DHRS4 | C29: 0.031 | D29: 2 | E29: 1736 | F29: 238 | G29: 0.004 | H29: Neg | I29: 566 | J29: 0.44 | K29: Neg
A30: ACOT8 | B30: ACOT8 | C30: 0.113 | D30: 2 | E30: 3140 | F30: 1642 | G30: 0.03 | H30: Neg | I30: 2342 | J30: 1.79 | K30: Neg
A31: ACOT8 | B31: DHRS4 | C31: 0.039 | D31: 1 | E31: 2076 | F31: 578 | G31: 0.01 | H31: Neg | I31: 821 | J31: 0.63 | K31: Neg
A32: ACOT8 | B32: HAO1 | C32: 0.031 | D32: 2 | E32: 2190 | F32: 692 | G32: 0.013 | H32: Neg | I32: 1021 | J32: 0.78 | K32: Neg
... A59: DAO | B59: DAO | C59: 0.033 | D59: 2 | E59: 2754 | F59: -593 | G59: -0.016 | H59: Neg | I59: 9112 | J59: 6.25 | K59: Pos
A60: DECR2 | B60: ACAA1a | C60: 0.031 | D60: 2 | E60: 4437 | F60: 1090 | G60: 0.029 | H60: Neg
A61: DECR2 | B61: DECR2 | C61: 0.116 | D61: 2 | E61: 2354 | F61: -993 | G61: -0.026 | H61: Neg | I61: 5024 | J61: 2.44 | K61: Pos
A62: DHRS4 | B62: DHRS4 | C62: 0.142 | D62: 1 | E62: 3438 | F62: 91 | G62: 0.002 | H62: Neg | I62: 1985 | J62: 0.97 | K62: Neg
A63: DHRS4 | B63: IDE | C63: 0.032 | D63: 1 | E63: 3746 | F63: 399 | G63: 0.01 | H63: Neg | I63: 1941 | J63: 0.94 | K63: Neg
A64: DNM1L | B64: DNM1L | C64: 0.221 | D64: 2 | E64: 8486 | F64: 5139 | G64: 0.135 | H64: Pos | I64: 9747 | J64: 4.74 | K64: Pos
A65: DNM1L | B65: ECH1 | C65: 0.035 | D65: 2 | E65: 3688 | F65: 341 | G65: 0.009 | H65: Neg | I65: 1890 | J65: 0.92 | K65: Neg
A66: ECH1 | B66: AMACR | C66: 0.032 | D66: 1 | E66: 4009 | F66: 662 | G66: 0.017 | H66: Neg | I66: 1984 | J66: 1.19 | K66: Neg
...

Sheet Controls-Split
A1: Split YFP Kontrollen
B2: Mean | E2: stab | H2: proz | L2: Hits Split | M2: Count | N2: Proz
A3: Platte | B3: Positiv | C3: P-nodna | D3: nodna | E3: nodna | F3: 3-fach | G3: 9-fach | H3: nodna | I3: 3-fach | J3: 9-fach | L3: Pos | M3: =COUNTIF(All!L3:L431,'Controls-Split'!L3:L4) -> 134 | N3: =M3/M6 -> 0.31678487
A4: 1 | B4: 56773 | C4: =B4-D4 -> 55275 | D4: 1498 | E4: 259 | F4: =D4+3*E4 -> 2275 | G4: =D4+9*E4 -> 3829 | H4: =E4/$B4 -> 0.0045620277 | I4: =F4/$B4 -> 0.040071865 | J4: =G4/$B4 -> 0.067444031 | L4: Neg | M4: =COUNTIF(All!L3:L431,'Controls-Split'!L3:L4) -> 289 | N4: =M4/M6 -> 0.68321513
A5: 2 | B5: 41457 | C5: =B5-D5 -> 38110 | D5: 3347 | E5: 614 | F5: =D5+3*E5 -> 5189 | G5: =D5+9*E5 -> 8873 | H5: =E5/$B5 -> 0.014810527 | I5: =F5/$B5 -> 0.12516583 | J5: =G5/$B5 -> 0.21402899
A6: 3 | B6: 46292 | C6: =B6-D6 -> 45549 | D6: 743 | E6: 289 | F6: =D6+3*E6 -> 1610 | G6: =D6+9*E6 -> 3344 | H6: =E6/$B6 -> 0.0062429793 | I6: =F6/$B6 -> 0.034779228 | J6: =G6/$B6 -> 0.072237104 | L6: Summe | M6: =M3+M4 -> 423
A7: 4 | B7: 62955 | C7: =B7-D7 -> 61597 | D7: 1358 | E7: 172 | F7: =D7+3*E7 -> 1874 | G7: =D7+9*E7 -> 2906 | H7: =E7/$B7 -> 0.0027321102 | I7: =F7/$B7 -> 0.029767294 | J7: =G7/$B7 -> 0.046159956
A8: 5 | B8: 45963 | C8: =B8-D8 -> 45328.6 | D8: 634.4 | E8: 100 | F8: =D8+3*E8 -> 934.4 | G8: =D8+9*E8 -> 1534.4 | H8: =E8/$B8 -> 0.002175663 | I8: =F8/$B8 -> 0.020329395 | J8: =G8/$B8 -> 0.033383374 | L8: Hits LUMIER | M8: Count | N8: Proz
A9: 6 | B9: 71656 | C9: =B9-D9 -> 69105 | D9: 2551 | E9: 965 | F9: =D9+3*E9 -> 5446 | G9: =D9+9*E9 -> 11236 | H9: =E9/$B9 -> 0.013467121 | I9: =F9/$B9 -> 0.07600201 | J9: =G9/$B9 -> 0.15680473 | L9: Pos | M9: =COUNTIF(All!R3:R431,'Controls-Split'!L9:L10) -> 85 | N9: =M9/M12 -> 0.20481928
A10: 7 | B10: 59704 | C10: =B10-D10 -> 58631.125 | D10: 1072.875 | E10: 87.7 | F10: =D10+3*E10 -> 1335.975 | G10: =D10+9*E10 -> 1862.175 | H10: =E10/$B10 -> 0.0014689133 | I10: =F10/$B10 -> 0.022376641 | J10: =G10/$B10 -> 0.031190121 | L10: Neg | M10: =COUNTIF(All!R3:R431,'Controls-Split'!L9:L10) -> 330 | N10: =M10/M12 -> 0.79518072
A11: 8 | B11: 81288 | C11: =B11-D11 -> 80139 | D11: 1149 | E11: 194 | F11: =D11+3*E11 -> 1731 | G11: =D11+9*E11 -> 2895 | H11: =E11/$B11 -> 0.0023865761 | I11: =F11/$B11 -> 0.021294656 | J11: =G11/$B11 -> 0.035614113
A12: 9 | B12: 53427 | C12: =B12-D12 -> 52223 | D12: 1204 | E12: 196 | F12: =D12+3*E12 -> 1792 | G12: =D12+9*E12 -> 2968 | H12: =E12/$B12 -> 0.0036685571 | I12: =F12/$B12 -> 0.033541093 | J12: =G12/$B12 -> 0.055552436 | L12: Summe | M12: =M9+M10 -> 415
A13: 10 | B13: 62147 | C13: =B13-D13 -> 61147 | D13: 1000 | E13: 123 | F13: =D13+3*E13 -> 1369 | G13: =D13+9*E13 -> 2107 | H13: =E13/$B13 -> 0.0019791784 | I13: =F13/$B13 -> 0.022028416 | J13: =G13/$B13 -> 0.033903487
A14: 11 | B14: 43295 | C14: =B14-D14 -> 42506 | D14: 789 | E14: 287 | F14: =D14+3*E14 -> 1650 | G14: =D14+9*E14 -> 3372 | H14: =E14/$B14 -> 0.006628941 | I14: =F14/$B14 -> 0.038110636 | J14: =G14/$B14 -> 0.077884282
A15: 12 | F15: =D15+3*E15 -> 0 | G15: =D15+9*E15 -> 0 | H15: =E15/$B15 -> #DIV/0! | I15: =F15/$B15 -> #DIV/0! | J15: =G15/$B15 -> #DIV/0!
A16: 13 | B16: 40961.5 | C16: =B16-D16 -> 39728.25 | D16: 1233.25 | E16: 183 | F16: =D16+3*E16 -> 1782.25 | G16: =D16+9*E16 -> 2880.25 | H16: =E16/$B16 -> 0.0044676098 | I16: =F16/$B16 -> 0.043510369 | J16: =G16/$B16 -> 0.070316028
A18: Mean | B18: =AVERAGE(B4:B17) -> 55493.208 | C18: =AVERAGE(C4:C17) -> 54111.581 | D18: =AVERAGE(D4:D17) -> 1381.6271 | E18: =_xlfn.STDEV.P(D4:D17) -> 758.85187
A21: LUMIER Kontrollen
B22: Mean | E22: stab | H22: WT-N-hRluc | L22: positiv, wenn signal > größer 9-fach Stab nodna
A23: Platte | B23: Positiv | C23: P/nodna | D23: nodna | E23: nodna | F23: 3-fach | G23: 9-fach | J23: CutOff
A24: 1 | B24: 370689.5 | C24: =B24/D24 -> 192.46599 | D24: 1926 | E24: 326
A25: 2
A26: 3 | B26: 48525 | C26: =B26/D26 -> 25.051626 | D26: 1937 | E26: 37 | F26: =D26+3*E26 -> 2048 | G26: =D26+9*E26 -> 2270 | H26: 0 | J26: =G26/D26 -> 1.1719153 | K26: cave, keine WT-N-hRluc Kontrolle auf Platte, daher hier 2 als Ratio
A27: 4 | B27: 322425 | C27: =B27/D27 -> 156.89781 | D27: 2055 | E27: 115 | F27: =D27+3*E27 -> 2400 | G27: =D27+9*E27 -> 3090 | H27: 4559 | J27: =G27/D27 -> 1.5036496
A28: 5 | B28: 252181 | C28: =B28/D28 -> 168.57019 | D28: 1496 | E28: 227 | F28: =D28+3*E28 -> 2177 | G28: =D28+9*E28 -> 3539 | H28: 2104 | J28: =G28/D28 -> 2.3656417 | K28: 3-fach Stab > WT-N-hRluc
A29: 6 | B29: 162675 | C29: =B29/D29 -> 131.93431 | D29: 1233 | E29: 105 | F29: =D29+3*E29 -> 1548 | G29: =D29+9*E29 -> 2178 | H29: 1923 | J29: =G29/D29 -> 1.7664234
A30: 7 | B30: 182381 | C30: =B30/D30 -> 140.50924 | D30: 1298 | E30: 101 | F30: =D30+3*E30 -> 1601 | G30: =D30+9*E30 -> 2207 | H30: 2158 | J30: =G30/D30 -> 1.7003082
A31: 8 | B31: 852928 | C31: =B31/D31 -> 316.25065 | D31: 2697 | E31: 103 | F31: =D31+3*E31 -> 3006 | G31: =D31+9*E31 -> 3624 | H31: 7129 | J31: =G31/D31 -> 1.3437152
A32: 9 | B32: 776590 | C32: =B32/D32 -> 312.76279 | D32: 2483 | E32: 407 | F32: =D32+3*E32 -> 3704 | G32: =D32+9*E32 -> 6146 | H32: 7206 | J32: =G32/D32 -> 2.4752316
A33: 10 | B33: 730388 | C33: =B33/D33 -> 283.97667 | D33: 2572 | E33: 769 | F33: =D33+3*E33 -> 4879 | G33: =D33+9*E33 -> 9493 | H33: 20631 | J33: =G33/D33 -> 3.690902
A34: 11 | B34: 138321 | C34: =B34/D34 -> 105.9931 | D34: 1305 | E34: 167 | F34: =D34+3*E34 -> 1806 | G34: =D34+9*E34 -> 2808 | H34: 1532 | J34: =G34/D34 -> 2.1517241
A35: 12 | B35: 230412 | C35: =B35/D35 -> 157.92461 | D35: 1459 | E35: 256 | F35: =D35+3*E35 -> 2227 | G35: =D35+9*E35 -> 3763 | H35: 2585 | J35: =G35/D35 -> 2.5791638

Sheet Blatt1
A1: Nicht gefunden | G1: Mit Split YFP gefunden
A2: N-hRluc | B2: N-Venus | C2: Neg | D2: 148 | E2: 0.51211073 | G2: N-hRluc | H2: N-Venus | I2: Pos | J2: 64 | K2: 0.47761194
A3: C-hRluc | B3: N-Venus | C3: Neg | D3: 48 | E3: 0.16608997 | G3: C-hRluc | H3: N-Venus | I3: Pos | J3: 40 | K3: 0.29850746
A4: C-hRluc | B4: C-Venus | C4: Neg | D4: 33 | E4: 0.11418685 | G4: C-hRluc | H4: C-Venus | I4: Pos | J4: 18 | K4: 0.13432836
A5: N-hRluc | B5: C-Venus | C5: Neg | D5: 60 | E5: 0.20761246 | G5: N-hRluc | H5: C-Venus | I5: Pos | J5: 12 | K5: 0.089552239
D6: 289 | J6: 134
H8: neg | I8: pos
G9: mean bret ratio | H9: 0.05038 | I9: 0.05429

Sheet GO BP
C1: n overl terms | D1: z-score | E1: sim score | F1: best overlapping term
A2: PHYH | B2: SLC27A2 | C2: 2 | D2: 6.028911 | E2: 1 | F2: methyl-branched fatty acid metabolic process
A3: PEX1 | B3: PEX13 | C3: 2 | D3: 6.028911 | E3: 1 | F3: microtubule-based peroxisome localization
A4: PEX5 | B4: PEX14 | C4: 2 | D4: 6.028911 | E4: 1 | F4: negative regulation of protein homotetramerization
A5: PECR | B5: ALDH3A2 | C5: 2 | D5: 6.028911 | E5: 1 | F5: phytol metabolic process
A6: IDI1 | B6: IDI2 | C6: 2 | D6: 6.028911 | E6: 1 | F6: dimethylallyl diphosphate biosynthetic process
A7: PMVK | B7: MVK | C7: 3 | D7: 5.648437 | E7: 0.66666667 | F7: isopentenyl diphosphate biosynthetic process, mevalonate pathway
A8: PEX14 | B8: PEX6 | C8: 3 | D8: 5.648437 | E8: 0.66666667 | F8: protein import into peroxisome matrix, translocation
A9: PEX11B | B9: PEX11A | C9: 3 | D9: 5.648437 | E9: 0.66666667 | F9: regulation of peroxisome size
A10: PEX11G | B10: PEX11A | C10: 3 | D10: 5.648437 | E10: 0.66666667 | F10: regulation of peroxisome size
A11: PEX11G | B11: PEX11B | C11: 3 | D11: 5.648437 | E11: 0.66666667 | F11: regulation of peroxisome size
A12: PEX5 | B12: PEX6 | C12: 3 | D12: 5.648437 | E12: 0.66666667 | F12: protein import into peroxisome matrix, translocation
A13: PEX11A | B13: PEX3 | C13: 4 | D13: 5.3784863 | E13: 0.5 | F13: peroxisome membrane biogenesis
... A1211: HSD17B4 | B1211: MVK | C1211: 1270 | D1211: -0.026941381 | E1211: 0.0015748031 | F1211: small molecule metabolic process

Sheet GO MF
C1: n overl terms | D1: z-score | E1: sim score | F1: best overlapping term
A2: IDI1 | B2: IDI2 | C2: 2 | D2: 6.028911 | E2: 1 | F2: isopentenyl-diphosphate delta-isomerase activity
A3: ACOT8 | B3: BAAT | C3: 2 | D3: 6.028911 | E3: 1 | F3: medium-chain acyl-CoA hydrolase activity
A4: ACOX2 | B4: ACOX1 | C4: 2 | D4: 6.028911 | E4: 1 | F4: acyl-CoA oxidase activity
A5: ACOX1 | B5: ACAA1 | C5: 2 | D5: 6.028911 | E5: 1 | F5: palmitoyl-CoA oxidase activity
A6: ACOX3 | B6: ACOX2 | C6: 2 | D6: 6.028911 | E6: 1 | F6: pristanoyl-CoA oxidase activity
A7: ECI2 | B7: EHHADH | C7: 2 | D7: 6.028911 | E7: 1 | F7: dodecenoyl-CoA delta-isomerase activity
A8: ACOT8 | B8: ACOT2 | C8: 3 | D8: 5.648437 | E8: 0.66666667 | F8: acyl-CoA hydrolase activity
A9: DDO | B9: DAO | C9: 4 | D9: 5.3784863 | E9: 0.5 | F9: oxidoreductase activity, acting on the CH-NH2 group of donors, oxygen as acceptor
A10: SOD2 | B10: SOD1 | C10: 5 | D10: 5.1690963 | E10: 0.4 | F10: superoxide dismutase activity
A11: SCP2 | B11: ACAA1 | C11: 5 | D11: 5.1690963 | E11: 0.4 | F11: transferase activity, transferring acyl groups other than amino-acyl groups
A12: PRDX1 | B12: PRDX5 | C12: 5 | D12: 5.1690963 | E12: 0.4 | F12: peroxiredoxin activity
A13: SLC27A2 | B13: ACSL4 | C13: 6 | D13: 4.9980123 | E13: 0.33333333 | F13: very long-chain fatty acid-CoA ligase activity
... A1675: PEX3 | B1675: PEX13 | C1675: 8076 | D1675: -1.7628029 | E1675: 0.00024764735 | F1675: protein binding

Sheet summaryNetworkFiltered
A1: PEX6 | B1: PEX5 | C1: 4 | D1: int | E1: go | F1: go | G1: hpo
A2: PEX5 | B2: PEX16 | C2: 4 | D2: int | E2: go | F2: go | G2: hpo
A3: PEX5 | B3: ACOX1 | C3: 4 | D3: int | E3: go | F3: go | G3: hpo
A4: PEX26 | B4: PEX16 | C4: 4 | D4: int | E4: go | F4: go | G4: hpo
A5: PEX26 | B5: PEX12 | C5: 4 | D5: int | E5: go | F5: go | G5: hpo
A6: PEX19 | B6: PEX5 | C6: 4 | D6: int | E6: go | F6: go | G6: hpo
A7: PEX19 | B7: PEX26 | C7: 4 | D7: int | E7: go | F7: go | G7: hpo
A8: PEX19 | B8: ACOX1 | C8: 4 | D8: int | E8: go | F8: go | G8: hpo
A9: PEX14 | B9: PEX5 | C9: 4 | D9: int | E9: go | F9: go | G9: hpo
A10: PEX14 | B10: PEX19 | C10: 4 | D10: int | E10: go | F10: go | G10: hpo
A11: PEX12 | B11: PEX5 | C11: 4 | D11: int | E11: go | F11: go | G11: hpo
A12: PEX12 | B12: PEX16 | C12: 4 | D12: int | E12: go | F12: go | G12: hpo
... A17: PEX1 | B17: PEX5 | C17: 4 | D17: int | E17: go | F17: go | G17: hpo
A18: PEX7 | B18: AGPS | C18: 3 | D18: int | E18: go | F18: hpo
A19: PEX6 | B19: PEX26 | C19: 3 | D19: int | E19: go | F19: hpo
A20: PEX6 | B20: PEX19 | C20: 3 | D20: int | E20: go | F20: hpo
A21: PEX5 | B21: HSD17B4 | C21: 3 | D21: int | E21: go | F21: hpo
A22: PEX5 | B22: ABCD3 | C22: 3 | D22: int | E22: go | F22: hpo
A23: PEX3 | B23: PEX19 | C23: 3 | D23: int | E23: go | F23: hpo
A24: PEX3 | B24: PEX16 | C24: 3 | D24: int | E24: go | F24: hpo
A25: PEX26 | B25: PEX5 | C25: 3 | D25: go | E25: go | F25: hpo
A26: PEX19 | B26: PEX16 | C26: 3 | D26: int | E26: go | F26: hpo
A27: PEX19 | B27: PEX12 | C27: 3 | D27: int | E27: go | F27: hpo
A28: PEX19 | B28: ABCD3 | C28: 3 | D28: int | E28: go | F28: hpo
A29: PEX19 | B29: ABCD1 | C29: 3 | D29: int | E29: go | F29: hpo
... A48: ABCD1 | B48: PEX5 | C48: 3 | D48: int | E48: go | F48: hpo
A49: SOD2 | B49: SOD1 | C49: 2 | D49: go | E49: go
A50: SLC27A2 | B50: ACSL6 | C50: 2 | D50: go | E50: go
A51: SCP2 | B51: HSD17B4 | C51: 2 | D51: go | E51: hpo
A52: SCP2 | B52: AMACR | C52: 2 | D52: go | E52: hpo
A53: PHYH | B53: MLYCD | C53: 2 | D53: int | E53: hpo
A54: PHYH | B54: HACL1 | C54: 2 | D54: go | E54: go
A55: PEX7 | B55: SCP2 | C55: 2 | D55: go | E55: hpo
A56: PEX7 | B56: PHYH | C56: 2 | D56: int | E56: hpo
A57: PEX7 | B57: PEX5 | C57: 2 | D57: go | E57: hpo
A58: PEX7 | B58: PEX3 | C58: 2 | D58: go | E58: hpo
A59: PEX7 | B59: PEX26 | C59: 2 | D59: go | E59: hpo
A60: PEX7 | B60: PEX16 | C60: 2 | D60: go | E60: hpo
... A217: ABCD1 | B217: ALDH3A2 | C217: 2 | D217: int | E217: hpo
A218: ZADH2 | B218: ZADH2 | C218: 1 | D218: int
...
